Workbook

Sheet 안내
A1: RAG 단계별 체크리스트 (엑셀판) rev.5
A2: 2026-09-21 · rag_checklist_sheet_rev5.html 과 같은 내용 · 소스별 컬럼 정의서 포함 · 사내 확인용
A4: 항목 | B4: 내용
A5: 이 파일 | B5: HTML 간소화 시트 rev3의 엑셀판. 사내에서 직접 고치며 쓰는 용도
A6: 입력하는 칸 | B6: 연노랑 칸만 입력: 현 수준 · 상태(드롭다운) · 메모 · 문서 수 · 스모크 판정
A7: 상태 값 | B7: 미확인 / 확인중 / 완료 / 해당없음 — 드롭다운에서 선택하면 색이 자동으로 바뀜
A8: 자동 계산 | B8: 요약 시트와 소스별 매트릭스는 수식. 상세 시트의 상태를 바꾸면 자동 갱신 (직접 입력하지 않음)
A9: 입력 예시 | B9: P1_적재공통 시트 S01 1행: 현 수준 = 'doc id 있음, 재수집 시 중복 체크 중', 상태 = 완료
A10: 우선순위 | B10: P0 먼저 확인 · P1 다음 · P2 필요할 때
A11: 시트 순서 | B11: 요약 → 소스별_매트릭스 → 소스별_상세 → 처리흐름_도식 → 처리흐름_판단기준 → P1_적재공통 → P1_검색 → P2_센싱 → P3_정형연계 → 정형연계_패턴 → 스모크20
A12: Phase 3 | B12: 정형 데이터 연계(S22~S29). 지표 정의서 양식은 metric_catalog_template_rev1.xlsx, 코드는 rag_lab/nb07_sql_router.py
A13: 소스별_컬럼정의 | B13: 소스 유형마다 있어야 할 컬럼(권장안). J·K 열(사내 보유 · 사내 컬럼명)을 채우면 사내 현황 매핑표가 된다
A14: 사용자 확인값 출처 | B14: 2026-09-19 대화: doc id 원천키 · 재수집 중복 체크 · 작성일/수집일 분리 · 날짜 95% 보유 · 6축 전부 사용
A15: 도식 색 | B15: 회색 = 입력 · 청록 = 핵심 처리 · 분홍 = 제거 · 흰색 = 일반 · 연두 = 청킹/메타 산출

Sheet 요약
A1: 요약 — 단계별 · 소스별 진행 현황
A2: 전부 수식 · 각 시트의 상태 칸을 바꾸면 자동 갱신
A4: 구분 | B4: 코드 | C4: 이름 | D4: 항목 | E4: 완료 | F4: 확인중 | G4: 미확인 | H4: 완료율
A5: P1 적재 공통 | B5: S01 | C5: 수집 | D5: =COUNTIF('P1_적재공통'!$A:$A,B5) -> 3 | E5: =COUNTIFS('P1_적재공통'!$A:$A,B5,'P1_적재공통'!$H:$H,"완료") -> 2 | F5: =COUNTIFS('P1_적재공통'!$A:$A,B5,'P1_적재공통'!$H:$H,"확인중") -> 0 | G5: =D5-E5-F5-COUNTIFS('P1_적재공통'!$A:$A,B5,'P1_적재공통'!$H:$H,"해당없음") -> 1 | H5: =IF(D5=0,0,E5/D5) -> 0.66666667
A6: P1 적재 공통 | B6: S02 | C6: 파싱 | D6: =COUNTIF('P1_적재공통'!$A:$A,B6) -> 2 | E6: =COUNTIFS('P1_적재공통'!$A:$A,B6,'P1_적재공통'!$H:$H,"완료") -> 0 | F6: =COUNTIFS('P1_적재공통'!$A:$A,B6,'P1_적재공통'!$H:$H,"확인중") -> 0 | G6: =D6-E6-F6-COUNTIFS('P1_적재공통'!$A:$A,B6,'P1_적재공통'!$H:$H,"해당없음") -> 2 | H6: =IF(D6=0,0,E6/D6) -> 0
A7: P1 적재 공통 | B7: S03 | C7: 청킹 | D7: =COUNTIF('P1_적재공통'!$A:$A,B7) -> 3 | E7: =COUNTIFS('P1_적재공통'!$A:$A,B7,'P1_적재공통'!$H:$H,"완료") -> 0 | F7: =COUNTIFS('P1_적재공통'!$A:$A,B7,'P1_적재공통'!$H:$H,"확인중") -> 0 | G7: =D7-E7-F7-COUNTIFS('P1_적재공통'!$A:$A,B7,'P1_적재공통'!$H:$H,"해당없음") -> 3 | H7: =IF(D7=0,0,E7/D7) -> 0
A8: P1 적재 공통 | B8: S04 | C8: 임베딩 | D8: =COUNTIF('P1_적재공통'!$A:$A,B8) -> 3 | E8: =COUNTIFS('P1_적재공통'!$A:$A,B8,'P1_적재공통'!$H:$H,"완료") -> 0 | F8: =COUNTIFS('P1_적재공통'!$A:$A,B8,'P1_적재공통'!$H:$H,"확인중") -> 0 | G8: =D8-E8-F8-COUNTIFS('P1_적재공통'!$A:$A,B8,'P1_적재공통'!$H:$H,"해당없음") -> 3 | H8: =IF(D8=0,0,E8/D8) -> 0
A9: P1 적재 공통 | B9: S05 | C9: 메타데이터 | D9: =COUNTIF('P1_적재공통'!$A:$A,B9) -> 3 | E9: =COUNTIFS('P1_적재공통'!$A:$A,B9,'P1_적재공통'!$H:$H,"완료") -> 0 | F9: =COUNTIFS('P1_적재공통'!$A:$A,B9,'P1_적재공통'!$H:$H,"확인중") -> 0 | G9: =D9-E9-F9-COUNTIFS('P1_적재공통'!$A:$A,B9,'P1_적재공통'!$H:$H,"해당없음") -> 3 | H9: =IF(D9=0,0,E9/D9) -> 0
A10: P1 적재 공통 | B10: S06 | C10: 벡터 DB | D10: =COUNTIF('P1_적재공통'!$A:$A,B10) -> 3 | E10: =COUNTIFS('P1_적재공통'!$A:$A,B10,'P1_적재공통'!$H:$H,"완료") -> 0 | F10: =COUNTIFS('P1_적재공통'!$A:$A,B10,'P1_적재공통'!$H:$H,"확인중") -> 0 | G10: =D10-E10-F10-COUNTIFS('P1_적재공통'!$A:$A,B10,'P1_적재공통'!$H:$H,"해당없음") -> 3 | H10: =IF(D10=0,0,E10/D10) -> 0
A11: P1 검색 | B11: S07 | C11: 질의 입력 | D11: =COUNTIF('P1_검색'!$A:$A,B11) -> 2 | E11: =COUNTIFS('P1_검색'!$A:$A,B11,'P1_검색'!$H:$H,"완료") -> 0 | F11: =COUNTIFS('P1_검색'!$A:$A,B11,'P1_검색'!$H:$H,"확인중") -> 1 | G11: =D11-E11-F11-COUNTIFS('P1_검색'!$A:$A,B11,'P1_검색'!$H:$H,"해당없음") -> 1 | H11: =IF(D11=0,0,E11/D11) -> 0
A12: P1 검색 | B12: S08 | C12: 질의 분석 · 분해 | D12: =COUNTIF('P1_검색'!$A:$A,B12) -> 3 | E12: =COUNTIFS('P1_검색'!$A:$A,B12,'P1_검색'!$H:$H,"완료") -> 0 | F12: =COUNTIFS('P1_검색'!$A:$A,B12,'P1_검색'!$H:$H,"확인중") -> 0 | G12: =D12-E12-F12-COUNTIFS('P1_검색'!$A:$A,B12,'P1_검색'!$H:$H,"해당없음") -> 3 | H12: =IF(D12=0,0,E12/D12) -> 0
A13: P1 검색 | B13: S09 | C13: BM25 | D13: =COUNTIF('P1_검색'!$A:$A,B13) -> 3 | E13: =COUNTIFS('P1_검색'!$A:$A,B13,'P1_검색'!$H:$H,"완료") -> 0 | F13: =COUNTIFS('P1_검색'!$A:$A,B13,'P1_검색'!$H:$H,"확인중") -> 0 | G13: =D13-E13-F13-COUNTIFS('P1_검색'!$A:$A,B13,'P1_검색'!$H:$H,"해당없음") -> 3 | H13: =IF(D13=0,0,E13/D13) -> 0
A14: P1 검색 | B14: S10 | C14: 시맨틱 검색 | D14: =COUNTIF('P1_검색'!$A:$A,B14) -> 2 | E14: =COUNTIFS('P1_검색'!$A:$A,B14,'P1_검색'!$H:$H,"완료") -> 0 | F14: =COUNTIFS('P1_검색'!$A:$A,B14,'P1_검색'!$H:$H,"확인중") -> 0 | G14: =D14-E14-F14-COUNTIFS('P1_검색'!$A:$A,B14,'P1_검색'!$H:$H,"해당없음") -> 2 | H14: =IF(D14=0,0,E14/D14) -> 0
A15: P1 검색 | B15: S11 | C15: 결합 · 다양성 | D15: =COUNTIF('P1_검색'!$A:$A,B15) -> 3 | E15: =COUNTIFS('P1_검색'!$A:$A,B15,'P1_검색'!$H:$H,"완료") -> 0 | F15: =COUNTIFS('P1_검색'!$A:$A,B15,'P1_검색'!$H:$H,"확인중") -> 0 | G15: =D15-E15-F15-COUNTIFS('P1_검색'!$A:$A,B15,'P1_검색'!$H:$H,"해당없음") -> 3 | H15: =IF(D15=0,0,E15/D15) -> 0
A16: P1 검색 | B16: S12 | C16: 리랭크 | D16: =COUNTIF('P1_검색'!$A:$A,B16) -> 2 | E16: =COUNTIFS('P1_검색'!$A:$A,B16,'P1_검색'!$H:$H,"완료") -> 0 | F16: =COUNTIFS('P1_검색'!$A:$A,B16,'P1_검색'!$H:$H,"확인중") -> 0 | G16: =D16-E16-F16-COUNTIFS('P1_검색'!$A:$A,B16,'P1_검색'!$H:$H,"해당없음") -> 2 | H16: =IF(D16=0,0,E16/D16) -> 0
A17: P1 검색 | B17: S13 | C17: 컨텍스트 | D17: =COUNTIF('P1_검색'!$A:$A,B17) -> 2 | E17: =COUNTIFS('P1_검색'!$A:$A,B17,'P1_검색'!$H:$H,"완료") -> 0 | F17: =COUNTIFS('P1_검색'!$A:$A,B17,'P1_검색'!$H:$H,"확인중") -> 0 | G17: =D17-E17-F17-COUNTIFS('P1_검색'!$A:$A,B17,'P1_검색'!$H:$H,"해당없음") -> 2 | H17: =IF(D17=0,0,E17/D17) -> 0
A18: P1 검색 | B18: S14 | C18: LLM 답변 | D18: =COUNTIF('P1_검색'!$A:$A,B18) -> 3 | E18: =COUNTIFS('P1_검색'!$A:$A,B18,'P1_검색'!$H:$H,"완료") -> 0 | F18: =COUNTIFS('P1_검색'!$A:$A,B18,'P1_검색'!$H:$H,"확인중") -> 0 | G18: =D18-E18-F18-COUNTIFS('P1_검색'!$A:$A,B18,'P1_검색'!$H:$H,"해당없음") -> 3 | H18: =IF(D18=0,0,E18/D18) -> 0
A19: P1 검색 | B19: S15 | C19: 평가 | D19: =COUNTIF('P1_검색'!$A:$A,B19) -> 3 | E19: =COUNTIFS('P1_검색'!$A:$A,B19,'P1_검색'!$H:$H,"완료") -> 0 | F19: =COUNTIFS('P1_검색'!$A:$A,B19,'P1_검색'!$H:$H,"확인중") -> 0 | G19: =D19-E19-F19-COUNTIFS('P1_검색'!$A:$A,B19,'P1_검색'!$H:$H,"해당없음") -> 3 | H19: =IF(D19=0,0,E19/D19) -> 0
A20: P2 센싱 | B20: S16 | C20: 센싱 축 | D20: =COUNTIF('P2_센싱'!$A:$A,B20) -> 2 | E20: =COUNTIFS('P2_센싱'!$A:$A,B20,'P2_센싱'!$H:$H,"완료") -> 1 | F20: =COUNTIFS('P2_센싱'!$A:$A,B20,'P2_센싱'!$H:$H,"확인중") -> 0 | G20: =D20-E20-F20-COUNTIFS('P2_센싱'!$A:$A,B20,'P2_센싱'!$H:$H,"해당없음") -> 1 | H20: =IF(D20=0,0,E20/D20) -> 0.5
A21: P2 센싱 | B21: S17 | C21: 상시 질의 | D21: =COUNTIF('P2_센싱'!$A:$A,B21) -> 2 | E21: =COUNTIFS('P2_센싱'!$A:$A,B21,'P2_센싱'!$H:$H,"완료") -> 0 | F21: =COUNTIFS('P2_센싱'!$A:$A,B21,'P2_센싱'!$H:$H,"확인중") -> 0 | G21: =D21-E21-F21-COUNTIFS('P2_센싱'!$A:$A,B21,'P2_센싱'!$H:$H,"해당없음") -> 2 | H21: =IF(D21=0,0,E21/D21) -> 0
A22: P2 센싱 | B22: S18 | C22: 검색 · 수집 | D22: =COUNTIF('P2_센싱'!$A:$A,B22) -> 2 | E22: =COUNTIFS('P2_센싱'!$A:$A,B22,'P2_센싱'!$H:$H,"완료") -> 0 | F22: =COUNTIFS('P2_센싱'!$A:$A,B22,'P2_센싱'!$H:$H,"확인중") -> 0 | G22: =D22-E22-F22-COUNTIFS('P2_센싱'!$A:$A,B22,'P2_센싱'!$H:$H,"해당없음") -> 2 | H22: =IF(D22=0,0,E22/D22) -> 0
A23: P2 센싱 | B23: S19 | C23: 변화 감지 | D23: =COUNTIF('P2_센싱'!$A:$A,B23) -> 3 | E23: =COUNTIFS('P2_센싱'!$A:$A,B23,'P2_센싱'!$H:$H,"완료") -> 0 | F23: =COUNTIFS('P2_센싱'!$A:$A,B23,'P2_센싱'!$H:$H,"확인중") -> 0 | G23: =D23-E23-F23-COUNTIFS('P2_센싱'!$A:$A,B23,'P2_센싱'!$H:$H,"해당없음") -> 3 | H23: =IF(D23=0,0,E23/D23) -> 0
A24: P2 센싱 | B24: S20 | C24: 요약 · 알림 | D24: =COUNTIF('P2_센싱'!$A:$A,B24) -> 2 | E24: =COUNTIFS('P2_센싱'!$A:$A,B24,'P2_센싱'!$H:$H,"완료") -> 0 | F24: =COUNTIFS('P2_센싱'!$A:$A,B24,'P2_센싱'!$H:$H,"확인중") -> 0 | G24: =D24-E24-F24-COUNTIFS('P2_센싱'!$A:$A,B24,'P2_센싱'!$H:$H,"해당없음") -> 2 | H24: =IF(D24=0,0,E24/D24) -> 0
A25: P2 센싱 | B25: S21 | C25: 백테스트 | D25: =COUNTIF('P2_센싱'!$A:$A,B25) -> 2 | E25: =COUNTIFS('P2_센싱'!$A:$A,B25,'P2_센싱'!$H:$H,"완료") -> 0 | F25: =COUNTIFS('P2_센싱'!$A:$A,B25,'P2_센싱'!$H:$H,"확인중") -> 0 | G25: =D25-E25-F25-COUNTIFS('P2_센싱'!$A:$A,B25,'P2_센싱'!$H:$H,"해당없음") -> 2 | H25: =IF(D25=0,0,E25/D25) -> 0
A26: P3 정형연계 | B26: S22 | C26: 정형 자산 카탈로그 | D26: =COUNTIF('P3_정형연계'!$A:$A,B26) -> 4 | E26: =COUNTIFS('P3_정형연계'!$A:$A,B26,'P3_정형연계'!$H:$H,"완료") -> 0 | F26: =COUNTIFS('P3_정형연계'!$A:$A,B26,'P3_정형연계'!$H:$H,"확인중") -> 0 | G26: =D26-E26-F26-COUNTIFS('P3_정형연계'!$A:$A,B26,'P3_정형연계'!$H:$H,"해당없음") -> 4 | H26: =IF(D26=0,0,E26/D26) -> 0
A27: P3 정형연계 | B27: S23 | C27: 시맨틱 뷰 · 허용목록 | D27: =COUNTIF('P3_정형연계'!$A:$A,B27) -> 4 | E27: =COUNTIFS('P3_정형연계'!$A:$A,B27,'P3_정형연계'!$H:$H,"완료") -> 0 | F27: =COUNTIFS('P3_정형연계'!$A:$A,B27,'P3_정형연계'!$H:$H,"확인중") -> 0 | G27: =D27-E27-F27-COUNTIFS('P3_정형연계'!$A:$A,B27,'P3_정형연계'!$H:$H,"해당없음") -> 4 | H27: =IF(D27=0,0,E27/D27) -> 0
A28: P3 정형연계 | B28: S24 | C28: 질의 라우팅 | D28: =COUNTIF('P3_정형연계'!$A:$A,B28) -> 4 | E28: =COUNTIFS('P3_정형연계'!$A:$A,B28,'P3_정형연계'!$H:$H,"완료") -> 0 | F28: =COUNTIFS('P3_정형연계'!$A:$A,B28,'P3_정형연계'!$H:$H,"확인중") -> 0 | G28: =D28-E28-F28-COUNTIFS('P3_정형연계'!$A:$A,B28,'P3_정형연계'!$H:$H,"해당없음") -> 4 | H28: =IF(D28=0,0,E28/D28) -> 0
A29: P3 정형연계 | B29: S25 | C29: SQL 생성 · 검증 | D29: =COUNTIF('P3_정형연계'!$A:$A,B29) -> 5 | E29: =COUNTIFS('P3_정형연계'!$A:$A,B29,'P3_정형연계'!$H:$H,"완료") -> 0 | F29: =COUNTIFS('P3_정형연계'!$A:$A,B29,'P3_정형연계'!$H:$H,"확인중") -> 0 | G29: =D29-E29-F29-COUNTIFS('P3_정형연계'!$A:$A,B29,'P3_정형연계'!$H:$H,"해당없음") -> 5 | H29: =IF(D29=0,0,E29/D29) -> 0
A30: P3 정형연계 | B30: S26 | C30: 정형 × 비정형 결합 | D30: =COUNTIF('P3_정형연계'!$A:$A,B30) -> 4 | E30: =COUNTIFS('P3_정형연계'!$A:$A,B30,'P3_정형연계'!$H:$H,"완료") -> 0 | F30: =COUNTIFS('P3_정형연계'!$A:$A,B30,'P3_정형연계'!$H:$H,"확인중") -> 0 | G30: =D30-E30-F30-COUNTIFS('P3_정형연계'!$A:$A,B30,'P3_정형연계'!$H:$H,"해당없음") -> 4 | H30: =IF(D30=0,0,E30/D30) -> 0
A31: P3 정형연계 | B31: S27 | C31: 수치 정합성 · 신뢰 | D31: =COUNTIF('P3_정형연계'!$A:$A,B31) -> 4 | E31: =COUNTIFS('P3_정형연계'!$A:$A,B31,'P3_정형연계'!$H:$H,"완료") -> 0 | F31: =COUNTIFS('P3_정형연계'!$A:$A,B31,'P3_정형연계'!$H:$H,"확인중") -> 0 | G31: =D31-E31-F31-COUNTIFS('P3_정형연계'!$A:$A,B31,'P3_정형연계'!$H:$H,"해당없음") -> 4 | H31: =IF(D31=0,0,E31/D31) -> 0
A32: P3 정형연계 | B32: S28 | C32: 권한 · 보안 | D32: =COUNTIF('P3_정형연계'!$A:$A,B32) -> 4 | E32: =COUNTIFS('P3_정형연계'!$A:$A,B32,'P3_정형연계'!$H:$H,"완료") -> 0 | F32: =COUNTIFS('P3_정형연계'!$A:$A,B32,'P3_정형연계'!$H:$H,"확인중") -> 0 | G32: =D32-E32-F32-COUNTIFS('P3_정형연계'!$A:$A,B32,'P3_정형연계'!$H:$H,"해당없음") -> 4 | H32: =IF(D32=0,0,E32/D32) -> 0
A33: P3 정형연계 | B33: S29 | C33: 평가 · 운영 | D33: =COUNTIF('P3_정형연계'!$A:$A,B33) -> 4 | E33: =COUNTIFS('P3_정형연계'!$A:$A,B33,'P3_정형연계'!$H:$H,"완료") -> 0 | F33: =COUNTIFS('P3_정형연계'!$A:$A,B33,'P3_정형연계'!$H:$H,"확인중") -> 0 | G33: =D33-E33-F33-COUNTIFS('P3_정형연계'!$A:$A,B33,'P3_정형연계'!$H:$H,"해당없음") -> 4 | H33: =IF(D33=0,0,E33/D33) -> 0
A34: 소스별 적재 | B34: NEWS | C34: 뉴스 | D34: =COUNTIF('소스별_상세'!$A:$A,C34) -> 5 | E34: =COUNTIFS('소스별_상세'!$A:$A,C34,'소스별_상세'!$I:$I,"완료") -> 0 | F34: =COUNTIFS('소스별_상세'!$A:$A,C34,'소스별_상세'!$I:$I,"확인중") -> 1 | G34: =D34-E34-F34-COUNTIFS('소스별_상세'!$A:$A,C34,'소스별_상세'!$I:$I,"해당없음") -> 4 | H34: =IF(D34=0,0,E34/D34) -> 0
A35: 소스별 적재 | B35: BROKER | C35: 증권사 리포트 | D35: =COUNTIF('소스별_상세'!$A:$A,C35) -> 5 | E35: =COUNTIFS('소스별_상세'!$A:$A,C35,'소스별_상세'!$I:$I,"완료") -> 0 | F35: =COUNTIFS('소스별_상세'!$A:$A,C35,'소스별_상세'!$I:$I,"확인중") -> 1 | G35: =D35-E35-F35-COUNTIFS('소스별_상세'!$A:$A,C35,'소스별_상세'!$I:$I,"해당없음") -> 4 | H35: =IF(D35=0,0,E35/D35) -> 0
A36: 소스별 적재 | B36: INSTITUTION | C36: 기관 보고서 | D36: =COUNTIF('소스별_상세'!$A:$A,C36) -> 5 | E36: =COUNTIFS('소스별_상세'!$A:$A,C36,'소스별_상세'!$I:$I,"완료") -> 0 | F36: =COUNTIFS('소스별_상세'!$A:$A,C36,'소스별_상세'!$I:$I,"확인중") -> 1 | G36: =D36-E36-F36-COUNTIFS('소스별_상세'!$A:$A,C36,'소스별_상세'!$I:$I,"해당없음") -> 4 | H36: =IF(D36=0,0,E36/D36) -> 0
A37: 소스별 적재 | B37: EMAIL | C37: 메일 | D37: =COUNTIF('소스별_상세'!$A:$A,C37) -> 5 | E37: =COUNTIFS('소스별_상세'!$A:$A,C37,'소스별_상세'!$I:$I,"완료") -> 0 | F37: =COUNTIFS('소스별_상세'!$A:$A,C37,'소스별_상세'!$I:$I,"확인중") -> 1 | G37: =D37-E37-F37-COUNTIFS('소스별_상세'!$A:$A,C37,'소스별_상세'!$I:$I,"해당없음") -> 4 | H37: =IF(D37=0,0,E37/D37) -> 0
A38: 소스별 적재 | B38: MEETING | C38: 회의록 | D38: =COUNTIF('소스별_상세'!$A:$A,C38) -> 5 | E38: =COUNTIFS('소스별_상세'!$A:$A,C38,'소스별_상세'!$I:$I,"완료") -> 0 | F38: =COUNTIFS('소스별_상세'!$A:$A,C38,'소스별_상세'!$I:$I,"확인중") -> 1 | G38: =D38-E38-F38-COUNTIFS('소스별_상세'!$A:$A,C38,'소스별_상세'!$I:$I,"해당없음") -> 4 | H38: =IF(D38=0,0,E38/D38) -> 0
A39: 소스별 적재 | B39: REPORT | C39: 사내 보고서 | D39: =COUNTIF('소스별_상세'!$A:$A,C39) -> 5 | E39: =COUNTIFS('소스별_상세'!$A:$A,C39,'소스별_상세'!$I:$I,"완료") -> 0 | F39: =COUNTIFS('소스별_상세'!$A:$A,C39,'소스별_상세'!$I:$I,"확인중") -> 1 | G39: =D39-E39-F39-COUNTIFS('소스별_상세'!$A:$A,C39,'소스별_상세'!$I:$I,"해당없음") -> 4 | H39: =IF(D39=0,0,E39/D39) -> 0
A40: 소스별 적재 | B40: KNOWLEDGE | C40: 지식문서 | D40: =COUNTIF('소스별_상세'!$A:$A,C40) -> 5 | E40: =COUNTIFS('소스별_상세'!$A:$A,C40,'소스별_상세'!$I:$I,"완료") -> 0 | F40: =COUNTIFS('소스별_상세'!$A:$A,C40,'소스별_상세'!$I:$I,"확인중") -> 1 | G40: =D40-E40-F40-COUNTIFS('소스별_상세'!$A:$A,C40,'소스별_상세'!$I:$I,"해당없음") -> 4 | H40: =IF(D40=0,0,E40/D40) -> 0
A41: 소스별 적재 | B41: ENG_REPORT | C41: 엔지니어 보고서 | D41: =COUNTIF('소스별_상세'!$A:$A,C41) -> 5 | E41: =COUNTIFS('소스별_상세'!$A:$A,C41,'소스별_상세'!$I:$I,"완료") -> 0 | F41: =COUNTIFS('소스별_상세'!$A:$A,C41,'소스별_상세'!$I:$I,"확인중") -> 1 | G41: =D41-E41-F41-COUNTIFS('소스별_상세'!$A:$A,C41,'소스별_상세'!$I:$I,"해당없음") -> 4 | H41: =IF(D41=0,0,E41/D41) -> 0
...

Sheet 소스별_매트릭스
A1: 소스별 매트릭스 — 소스 9종 × 적재 5단계
A2: 칸 = 상태(소스별_상세에서 자동) · 핵심 필요사항 · 우선 | 문서 수만 입력
A4: 소스 | B4: DOC_TYPE | C4: 구분 | D4: 문서 수 | E4: 수집 | F4: 파싱 | G4: 청킹 | H4: 메타 | I4: 권한 | J4: 보안등급
A5: 뉴스 | B5: NEWS | C5: 사외 | E5: =IFERROR(INDEX('소스별_상세'!$I$5:$I$49,MATCH($A5&"|"&E$4,'소스별_상세'!$L$5:$L$49,0)),"")&" · 재송고 중복 (P1)" -> 확인중 · 재송고 중복 (P1) | F5: =IFERROR(INDEX('소스별_상세'!$I$5:$I$49,MATCH($A5&"|"&F$4,'소스별_상세'!$L$5:$L$49,0)),"")&" · 본문만 추출 (P1)" -> 미확인 · 본문만 추출 (P1) | G5: =IFERROR(INDEX('소스별_상세'!$I$5:$I$49,MATCH($A5&"|"&G$4,'소스별_상세'!$L$5:$L$49,0)),"")&" · 기사 단위 (P0)" -> 미확인 · 기사 단위 (P0) | H5: =IFERROR(INDEX('소스별_상세'!$I$5:$I$49,MATCH($A5&"|"&H$4,'소스별_상세'!$L$5:$L$49,0)),"")&" · 태그 = 센싱 기반 (P0)" -> 미확인 · 태그 = 센싱 기반 (P0) | I5: =IFERROR(INDEX('소스별_상세'!$I$5:$I$49,MATCH($A5&"|"&I$4,'소스별_상세'!$L$5:$L$49,0)),"")&" · 전체 공개 (P2)" -> 미확인 · 전체 공개 (P2) | J5: 0
A6: 증권사 리포트 | B6: BROKER | C6: 사외 | E6: =IFERROR(INDEX('소스별_상세'!$I$5:$I$49,MATCH($A6&"|"&E$4,'소스별_상세'!$L$5:$L$49,0)),"")&" · 수정본 처리 (P1)" -> 확인중 · 수정본 처리 (P1) | F6: =IFERROR(INDEX('소스별_상세'!$I$5:$I$49,MATCH($A6&"|"&F$4,'소스별_상세'!$L$5:$L$49,0)),"")&" · 표 · 수치 보존 (P0)" -> 미확인 · 표 · 수치 보존 (P0) | G6: =IFERROR(INDEX('소스별_상세'!$I$5:$I$49,MATCH($A6&"|"&G$4,'소스별_상세'!$L$5:$L$49,0)),"")&" · 섹션 + 표 분리 (P0)" -> 미확인 · 섹션 + 표 분리 (P0) | H6: =IFERROR(INDEX('소스별_상세'!$I$5:$I$49,MATCH($A6&"|"&H$4,'소스별_상세'!$L$5:$L$49,0)),"")&" · 증권사 · 종목 (P1)" -> 미확인 · 증권사 · 종목 (P1) | I6: =IFERROR(INDEX('소스별_상세'!$I$5:$I$49,MATCH($A6&"|"&I$4,'소스별_상세'!$L$5:$L$49,0)),"")&" · 구독 범위 (P1)" -> 미확인 · 구독 범위 (P1) | J6: 0~1
A7: 기관 보고서 | B7: INSTITUTION | C7: 사외 | E7: =IFERROR(INDEX('소스별_상세'!$I$5:$I$49,MATCH($A7&"|"&E$4,'소스별_상세'!$L$5:$L$49,0)),"")&" · 정기본 누락 (P1)" -> 확인중 · 정기본 누락 (P1) | F7: =IFERROR(INDEX('소스별_상세'!$I$5:$I$49,MATCH($A7&"|"&F$4,'소스별_상세'!$L$5:$L$49,0)),"")&" · 헤딩 · 표 (P1)" -> 미확인 · 헤딩 · 표 (P1) | G7: =IFERROR(INDEX('소스별_상세'!$I$5:$I$49,MATCH($A7&"|"&G$4,'소스별_상세'!$L$5:$L$49,0)),"")&" · 헤딩 단위 (P1)" -> 미확인 · 헤딩 단위 (P1) | H7: =IFERROR(INDEX('소스별_상세'!$I$5:$I$49,MATCH($A7&"|"&H$4,'소스별_상세'!$L$5:$L$49,0)),"")&" · 기준 시점 ≠ 발행일 (P0)" -> 미확인 · 기준 시점 ≠ 발행일 (P0) | I7: =IFERROR(INDEX('소스별_상세'!$I$5:$I$49,MATCH($A7&"|"&I$4,'소스별_상세'!$L$5:$L$49,0)),"")&" · 라이선스 (P2)" -> 미확인 · 라이선스 (P2) | J7: 0~1
A8: 메일 | B8: EMAIL | C8: 사내 | E8: =IFERROR(INDEX('소스별_상세'!$I$5:$I$49,MATCH($A8&"|"&E$4,'소스별_상세'!$L$5:$L$49,0)),"")&" · 대상 범위 · 첨부 (P0)" -> 확인중 · 대상 범위 · 첨부 (P0) | F8: =IFERROR(INDEX('소스별_상세'!$I$5:$I$49,MATCH($A8&"|"&F$4,'소스별_상세'!$L$5:$L$49,0)),"")&" · 인용 · 서명 제거 (P0)" -> 미확인 · 인용 · 서명 제거 (P0) | G8: =IFERROR(INDEX('소스별_상세'!$I$5:$I$49,MATCH($A8&"|"&G$4,'소스별_상세'!$L$5:$L$49,0)),"")&" · 스레드 단위 (P0)" -> 미확인 · 스레드 단위 (P0) | H8: =IFERROR(INDEX('소스별_상세'!$I$5:$I$49,MATCH($A8&"|"&H$4,'소스별_상세'!$L$5:$L$49,0)),"")&" · thread_id (P1)" -> 미확인 · thread_id (P1) | I8: =IFERROR(INDEX('소스별_상세'!$I$5:$I$49,MATCH($A8&"|"&I$4,'소스별_상세'!$L$5:$L$49,0)),"")&" · 발신 + 수신자만 (P0)" -> 미확인 · 발신 + 수신자만 (P0) | J8: 1~2
A9: 회의록 | B9: MEETING | C9: 사내 | E9: =IFERROR(INDEX('소스별_상세'!$I$5:$I$49,MATCH($A9&"|"&E$4,'소스별_상세'!$L$5:$L$49,0)),"")&" · 양식 통일 (P1)" -> 확인중 · 양식 통일 (P1) | F9: =IFERROR(INDEX('소스별_상세'!$I$5:$I$49,MATCH($A9&"|"&F$4,'소스별_상세'!$L$5:$L$49,0)),"")&" · 안건 구조 (P1)" -> 미확인 · 안건 구조 (P1) | G9: =IFERROR(INDEX('소스별_상세'!$I$5:$I$49,MATCH($A9&"|"&G$4,'소스별_상세'!$L$5:$L$49,0)),"")&" · 안건 단위 (P0)" -> 미확인 · 안건 단위 (P0) | H9: =IFERROR(INDEX('소스별_상세'!$I$5:$I$49,MATCH($A9&"|"&H$4,'소스별_상세'!$L$5:$L$49,0)),"")&" · 참석자 · 과제 (P1)" -> 미확인 · 참석자 · 과제 (P1) | I9: =IFERROR(INDEX('소스별_상세'!$I$5:$I$49,MATCH($A9&"|"&I$4,'소스별_상세'!$L$5:$L$49,0)),"")&" · 참석자 + 부서 (P0)" -> 미확인 · 참석자 + 부서 (P0) | J9: 1~2
A10: 사내 보고서 | B10: REPORT | C10: 사내 | E10: =IFERROR(INDEX('소스별_상세'!$I$5:$I$49,MATCH($A10&"|"&E$4,'소스별_상세'!$L$5:$L$49,0)),"")&" · 최종본 · 버전 (P0)" -> 확인중 · 최종본 · 버전 (P0) | F10: =IFERROR(INDEX('소스별_상세'!$I$5:$I$49,MATCH($A10&"|"&F$4,'소스별_상세'!$L$5:$L$49,0)),"")&" · 형식 혼합 (P1)" -> 미확인 · 형식 혼합 (P1) | G10: =IFERROR(INDEX('소스별_상세'!$I$5:$I$49,MATCH($A10&"|"&G$4,'소스별_상세'!$L$5:$L$49,0)),"")&" · 슬라이드 단위 (P1)" -> 미확인 · 슬라이드 단위 (P1) | H10: =IFERROR(INDEX('소스별_상세'!$I$5:$I$49,MATCH($A10&"|"&H$4,'소스별_상세'!$L$5:$L$49,0)),"")&" · 보안등급 (P0)" -> 미확인 · 보안등급 (P0) | I10: =IFERROR(INDEX('소스별_상세'!$I$5:$I$49,MATCH($A10&"|"&I$4,'소스별_상세'!$L$5:$L$49,0)),"")&" · 등급 + 부서 (P0)" -> 미확인 · 등급 + 부서 (P0) | J10: 1~2
A11: 지식문서 | B11: KNOWLEDGE | C11: 사내 | E11: =IFERROR(INDEX('소스별_상세'!$I$5:$I$49,MATCH($A11&"|"&E$4,'소스별_상세'!$L$5:$L$49,0)),"")&" · 최신본만 (P1)" -> 확인중 · 최신본만 (P1) | F11: =IFERROR(INDEX('소스별_상세'!$I$5:$I$49,MATCH($A11&"|"&F$4,'소스별_상세'!$L$5:$L$49,0)),"")&" · 헤딩 보존 (P2)" -> 미확인 · 헤딩 보존 (P2) | G11: =IFERROR(INDEX('소스별_상세'!$I$5:$I$49,MATCH($A11&"|"&G$4,'소스별_상세'!$L$5:$L$49,0)),"")&" · 헤딩 단위 (P1)" -> 미확인 · 헤딩 단위 (P1) | H11: =IFERROR(INDEX('소스별_상세'!$I$5:$I$49,MATCH($A11&"|"&H$4,'소스별_상세'!$L$5:$L$49,0)),"")&" · 최종 수정일 (P1)" -> 미확인 · 최종 수정일 (P1) | I11: =IFERROR(INDEX('소스별_상세'!$I$5:$I$49,MATCH($A11&"|"&I$4,'소스별_상세'!$L$5:$L$49,0)),"")&" · 사내 전체 (P2)" -> 미확인 · 사내 전체 (P2) | J11: 1
A12: 엔지니어 보고서 | B12: ENG_REPORT | C12: 사내 | E12: =IFERROR(INDEX('소스별_상세'!$I$5:$I$49,MATCH($A12&"|"&E$4,'소스별_상세'!$L$5:$L$49,0)),"")&" · 과제별 범위 (P1)" -> 확인중 · 과제별 범위 (P1) | F12: =IFERROR(INDEX('소스별_상세'!$I$5:$I$49,MATCH($A12&"|"&F$4,'소스별_상세'!$L$5:$L$49,0)),"")&" · 측정 표 · 약어 (P1)" -> 미확인 · 측정 표 · 약어 (P1) | G12: =IFERROR(INDEX('소스별_상세'!$I$5:$I$49,MATCH($A12&"|"&G$4,'소스별_상세'!$L$5:$L$49,0)),"")&" · 섹션 + 표 (P1)" -> 미확인 · 섹션 + 표 (P1) | H12: =IFERROR(INDEX('소스별_상세'!$I$5:$I$49,MATCH($A12&"|"&H$4,'소스별_상세'!$L$5:$L$49,0)),"")&" · 공정 · 제품 (P1)" -> 미확인 · 공정 · 제품 (P1) | I12: =IFERROR(INDEX('소스별_상세'!$I$5:$I$49,MATCH($A12&"|"&I$4,'소스별_상세'!$L$5:$L$49,0)),"")&" · 과제 그룹 (P0)" -> 미확인 · 과제 그룹 (P0) | J12: 1~2
A13: 임원 보고서 | B13: EXEC_REPORT | C13: 사내 | E13: =IFERROR(INDEX('소스별_상세'!$I$5:$I$49,MATCH($A13&"|"&E$4,'소스별_상세'!$L$5:$L$49,0)),"")&" · 최종본 (P1)" -> 확인중 · 최종본 (P1) | F13: =IFERROR(INDEX('소스별_상세'!$I$5:$I$49,MATCH($A13&"|"&F$4,'소스별_상세'!$L$5:$L$49,0)),"")&" · 요약 슬라이드 (P1)" -> 미확인 · 요약 슬라이드 (P1) | G13: =IFERROR(INDEX('소스별_상세'!$I$5:$I$49,MATCH($A13&"|"&G$4,'소스별_상세'!$L$5:$L$49,0)),"")&" · 슬라이드 단위 (P1)" -> 미확인 · 슬라이드 단위 (P1) | H13: =IFERROR(INDEX('소스별_상세'!$I$5:$I$49,MATCH($A13&"|"&H$4,'소스별_상세'!$L$5:$L$49,0)),"")&" · 등급 3 (P1)" -> 미확인 · 등급 3 (P1) | I13: =IFERROR(INDEX('소스별_상세'!$I$5:$I$49,MATCH($A13&"|"&I$4,'소스별_상세'!$L$5:$L$49,0)),"")&" · 결재선만 · 누출 테스트 (P0)" -> 미확인 · 결재선만 · 누출 테스트 (P0) | J13: 3

Sheet 소스별_상세
A1: 소스별 상세 — 소스마다 수집 · 파싱 · 청킹 · 메타 · 권한
A2: 연노랑 칸만 입력 · L열(키)은 매트릭스 연결용 수식
A4: 소스 | B4: DOC_TYPE | C4: 구분 | D4: 단계 | E4: 체크 항목 | F4: 현 수준 | G4: 필요사항 | H4: 우선 | I4: 상태 | J4: 보안등급 | K4: 메모 | L4: 키
A5: 뉴스 | B5: NEWS | C5: 사외 | D5: 수집 | E5: 매체 목록 · 수집 주기 · 재송고 중복 | F5: 공통: doc id · 중복 체크 · 날짜 분리 확인 | G5: 재송고 근사 중복(MinHash) — 센싱에도 필수 | H5: P1 | I5: 확인중 | J5: 0 | L5: =A5&"|"&D5 -> 뉴스|수집
A6: 뉴스 | B6: NEWS | C6: 사외 | D6: 파싱 | E6: HTML 본문만 추출되는지 (광고 · 관련기사 · 기자 정보 제거) | G6: 본문 추출 규칙 점검 (샘플 10건) | H6: P1 | I6: 미확인 | J6: 0 | L6: =A6&"|"&D6 -> 뉴스|파싱
A7: 뉴스 | B7: NEWS | C7: 사외 | D7: 청킹 | E7: 기사 1건이 몇 청크로 쪼개지는지 | G7: 기사 = 1~2청크, 제목을 헤더로 | H7: P0 | I7: 미확인 | J7: 0 | L7: =A7&"|"&D7 -> 뉴스|청킹
A8: 뉴스 | B8: NEWS | C8: 사외 | D8: 메타 | E8: 발행일시 · 언론사 · 기자 · URL · 카테고리 | G8: + 회사 · 제품 태그 (센싱 핵심) | H8: P0 | I8: 미확인 | J8: 0 | L8: =A8&"|"&D8 -> 뉴스|메타
A9: 뉴스 | B9: NEWS | C9: 사외 | D9: 권한 | E9: 공개 문서 처리 | G9: 보안등급 0, ACL = ALL | H9: P2 | I9: 미확인 | J9: 0 | L9: =A9&"|"&D9 -> 뉴스|권한
A10: 증권사 리포트 | B10: BROKER | C10: 사외 | D10: 수집 | E10: 증권사 · 구독 범위 · PDF 수신 경로 | F10: 공통: doc id · 중복 체크 · 날짜 분리 확인 | G10: 같은 리포트 재수신 · 수정본 처리 | H10: P1 | I10: 확인중 | J10: 0~1 | L10: =A10&"|"&D10 -> 증권사 리포트|수집
A11: 증권사 리포트 | B11: BROKER | C11: 사외 | D11: 파싱 | E11: 표 · 차트 수치가 텍스트로 살아 있는지, 면책 문구 반복 | G11: 표는 Markdown 표로, 면책 · 머리글 제거 | H11: P0 | I11: 미확인 | J11: 0~1 | L11: =A11&"|"&D11 -> 증권사 리포트|파싱
A12: 증권사 리포트 | B12: BROKER | C12: 사외 | D12: 청킹 | E12: 섹션 · 표가 중간에 잘리는지 | G12: 섹션 단위 + 표는 별도 청크 | H12: P0 | I12: 미확인 | J12: 0~1 | L12: =A12&"|"&D12 -> 증권사 리포트|청킹
A13: 증권사 리포트 | B13: BROKER | C13: 사외 | D13: 메타 | E13: 발행일 · 증권사 · 애널리스트 · 대상 종목/산업 | G13: + 투자의견 · 목표가 (JSON) | H13: P1 | I13: 미확인 | J13: 0~1 | L13: =A13&"|"&D13 -> 증권사 리포트|메타
A14: 증권사 리포트 | B14: BROKER | C14: 사외 | D14: 권한 | E14: 구독 계약상 재배포 범위 | G14: 계약 범위 내 부서 · 그룹으로 제한 | H14: P1 | I14: 미확인 | J14: 0~1 | L14: =A14&"|"&D14 -> 증권사 리포트|권한
A15: 기관 보고서 | B15: INSTITUTION | C15: 사외 | D15: 수집 | E15: 기관 목록 · 유료/무료 · 발행 주기 | F15: 공통: doc id · 중복 체크 · 날짜 분리 확인 | G15: 정기 보고서 누락 여부 점검 | H15: P1 | I15: 확인중 | J15: 0~1 | L15: =A15&"|"&D15 -> 기관 보고서|수집
A16: 기관 보고서 | B16: INSTITUTION | C16: 사외 | D16: 파싱 | E16: 긴 PDF의 목차 · 헤딩 · 표 구조 | G16: 헤딩 구조 보존, 표 별도 | H16: P1 | I16: 미확인 | J16: 0~1 | L16: =A16&"|"&D16 -> 기관 보고서|파싱
A17: 기관 보고서 | B17: INSTITUTION | C17: 사외 | D17: 청킹 | E17: 장 · 절 단위로 잘리는지 | G17: 헤딩 기반 섹션, 표 별도 | H17: P1 | I17: 미확인 | J17: 0~1 | L17: =A17&"|"&D17 -> 기관 보고서|청킹
A18: 기관 보고서 | B18: INSTITUTION | C18: 사외 | D18: 메타 | E18: 발행일 vs 데이터 기준 시점 구분 | G18: 데이터 기준 시점 별도 기록 (예: 3Q26 데이터, 10월 발행) | H18: P0 | I18: 미확인 | J18: 0~1 | L18: =A18&"|"&D18 -> 기관 보고서|메타
A19: 기관 보고서 | B19: INSTITUTION | C19: 사외 | D19: 권한 | E19: 라이선스 범위 | G19: 라이선스 내 공유 범위 | H19: P2 | I19: 미확인 | J19: 0~1 | L19: =A19&"|"&D19 -> 기관 보고서|권한
A20: 메일 | B20: EMAIL | C20: 사내 | D20: 수집 | E20: 대상 메일함 범위 · 첨부 포함 여부 | F20: 공통: doc id · 중복 체크 · 날짜 분리 확인 | G20: 수집 대상 · 동의 범위 명확화, 첨부는 별도 문서 | H20: P0 | I20: 확인중 | J20: 1~2 | L20: =A20&"|"&D20 -> 메일|수집
A21: 메일 | B21: EMAIL | C21: 사내 | D21: 파싱 | E21: 인용 본문 · 서명 · 면책 문구가 섞여 있는지 | G21: 인용 · 서명 제거 규칙 | H21: P0 | I21: 미확인 | J21: 1~2 | L21: =A21&"|"&D21 -> 메일|파싱
A22: 메일 | B22: EMAIL | C22: 사내 | D22: 청킹 | E22: 답장마다 같은 내용이 반복되는지 | G22: 스레드 단위, 최신 답장 기준 | H22: P0 | I22: 미확인 | J22: 1~2 | L22: =A22&"|"&D22 -> 메일|청킹
A23: 메일 | B23: EMAIL | C23: 사내 | D23: 메타 | E23: 발신일 · 발신자 · 부서 · thread_id | G23: 수신자는 JSON이 아니라 ACL로 | H23: P1 | I23: 미확인 | J23: 1~2 | L23: =A23&"|"&D23 -> 메일|메타
A24: 메일 | B24: EMAIL | C24: 사내 | D24: 권한 | E24: 발신자 · 수신자 외 열람 차단 | G24: ACL = 발신자 + 수신자, 누출 테스트 | H24: P0 | I24: 미확인 | J24: 1~2 | L24: =A24&"|"&D24 -> 메일|권한
A25: 회의록 | B25: MEETING | C25: 사내 | D25: 수집 | E25: 저장 위치 · 양식 통일 여부 | F25: 공통: doc id · 중복 체크 · 날짜 분리 확인 | G25: 양식별 수집 규칙 | H25: P1 | I25: 확인중 | J25: 1~2 | L25: =A25&"|"&D25 -> 회의록|수집
A26: 회의록 | B26: MEETING | C26: 사내 | D26: 파싱 | E26: 안건 · 결정 · 액션 아이템 구조가 보존되는지 | G26: 구조 보존 파싱 | H26: P1 | I26: 미확인 | J26: 1~2 | L26: =A26&"|"&D26 -> 회의록|파싱
A27: 회의록 | B27: MEETING | C27: 사내 | D27: 청킹 | E27: 안건 단위로 잘리는지 | G27: 안건 = 1청크 | H27: P0 | I27: 미확인 | J27: 1~2 | L27: =A27&"|"&D27 -> 회의록|청킹
A28: 회의록 | B28: MEETING | C28: 사내 | D28: 메타 | E28: 회의일 · 주관 부서 · 참석자 · 프로젝트 코드 | G28: 액션 아이템 JSON | H28: P1 | I28: 미확인 | J28: 1~2 | L28: =A28&"|"&D28 -> 회의록|메타
A29: 회의록 | B29: MEETING | C29: 사내 | D29: 권한 | E29: 참석자 · 주관 부서 외 열람 | G29: ACL = 참석자 + 주관 부서 | H29: P0 | I29: 미확인 | J29: 1~2 | L29: =A29&"|"&D29 -> 회의록|권한
A30: 사내 보고서 | B30: REPORT | C30: 사내 | D30: 수집 | E30: 결재 완료본만인지, 초안 · 버전 중복 | F30: 공통: doc id · 중복 체크 · 날짜 분리 확인 | G30: 최종본만 적재, 버전 관리 | H30: P0 | I30: 확인중 | J30: 1~2 | L30: =A30&"|"&D30 -> 사내 보고서|수집
A31: 사내 보고서 | B31: REPORT | C31: 사내 | D31: 파싱 | E31: PPT · Excel · Word 혼합 — 슬라이드 텍스트 · 표 | G31: 형식별 파서, PPT 표 추출 | H31: P1 | I31: 미확인 | J31: 1~2 | L31: =A31&"|"&D31 -> 사내 보고서|파싱
A32: 사내 보고서 | B32: REPORT | C32: 사내 | D32: 청킹 | E32: 슬라이드 · 헤딩 단위로 잘리는지 | G32: 슬라이드 / 헤딩 단위 | H32: P1 | I32: 미확인 | J32: 1~2 | L32: =A32&"|"&D32 -> 사내 보고서|청킹
A33: 사내 보고서 | B33: REPORT | C33: 사내 | D33: 메타 | E33: 작성일 · 부서 · 작성자 · 버전 · 보안등급 | G33: 보안등급은 공통 컬럼 | H33: P0 | I33: 미확인 | J33: 1~2 | L33: =A33&"|"&D33 -> 사내 보고서|메타
A34: 사내 보고서 | B34: REPORT | C34: 사내 | D34: 권한 | E34: 보안등급 · 공유 범위 반영 | G34: 등급 + 부서 ACL | H34: P0 | I34: 미확인 | J34: 1~2 | L34: =A34&"|"&D34 -> 사내 보고서|권한
A35: 지식문서 | B35: KNOWLEDGE | C35: 사내 | D35: 수집 | E35: KMS 범위 · 갱신 이력 | F35: 공통: doc id · 중복 체크 · 날짜 분리 확인 | G35: 최신본만 유지 (구버전 삭제 반영) | H35: P1 | I35: 확인중 | J35: 1 | L35: =A35&"|"&D35 -> 지식문서|수집
A36: 지식문서 | B36: KNOWLEDGE | C36: 사내 | D36: 파싱 | E36: 위키 · HTML 구조 | G36: 헤딩 · 목록 보존 | H36: P2 | I36: 미확인 | J36: 1 | L36: =A36&"|"&D36 -> 지식문서|파싱
A37: 지식문서 | B37: KNOWLEDGE | C37: 사내 | D37: 청킹 | E37: 헤딩 단위로 잘리는지 | G37: 헤딩 기반 | H37: P1 | I37: 미확인 | J37: 1 | L37: =A37&"|"&D37 -> 지식문서|청킹
A38: 지식문서 | B38: KNOWLEDGE | C38: 사내 | D38: 메타 | E38: 최종 수정일 · 소관 부서 · 시스템명 | G38: 작성일보다 최종 수정일 기준 | H38: P1 | I38: 미확인 | J38: 1 | L38: =A38&"|"&D38 -> 지식문서|메타
A39: 지식문서 | B39: KNOWLEDGE | C39: 사내 | D39: 권한 | E39: 사내 전체 공개 여부 | G39: 보안등급 1 | H39: P2 | I39: 미확인 | J39: 1 | L39: =A39&"|"&D39 -> 지식문서|권한
A40: 엔지니어 보고서 | B40: ENG_REPORT | C40: 사내 | D40: 수집 | E40: 저장 위치 · 과제별 접근 | F40: 공통: doc id · 중복 체크 · 날짜 분리 확인 | G40: 과제 · 부서별 수집 범위 | H40: P1 | I40: 확인중 | J40: 1~2 | L40: =A40&"|"&D40 -> 엔지니어 보고서|수집
A41: 엔지니어 보고서 | B41: ENG_REPORT | C41: 사내 | D41: 파싱 | E41: 측정 표 · 그래프 · 수식 · 공정 약어 | G41: 표 별도, 약어 사전 | H41: P1 | I41: 미확인 | J41: 1~2 | L41: =A41&"|"&D41 -> 엔지니어 보고서|파싱
...

Sheet 소스별_컬럼정의
A1: 소스별 컬럼 정의서 — 어떤 컬럼이 있어야 하는가 (권장안)
A2: 연노랑 두 칸(사내 보유 · 사내 컬럼명)을 채우면 매핑표가 된다 · 필수 M / 권장 R / 선택 O
A4: 구분 | B4: 소스 | C4: 컬럼명 | D4: 논리명 | E4: 타입 | F4: 필수 | G4: 어디서 오나 | H4: 쓰이는 곳 | I4: 샘플값 | J4: 사내 보유 | K4: 사내 컬럼명
A5: 공통 | B5: 문서 | C5: DOC_ID | D5: 문서 고유 ID | E5: VARCHAR2(64) | F5: 필수 | G5: 적재 시 생성 (소스코드+일자+일련) | H5: S01 · 전 단계 키 | I5: NEWS_20260915_000123
A6: 공통 | B6: 문서 | C6: SRC_SYSTEM | D6: 원천 시스템 | E6: VARCHAR2(32) | F6: 필수 | G6: 수집 모듈 | H6: S01 증분 · 재수집 | I6: NEWS_CRAWL
A7: 공통 | B7: 문서 | C7: SRC_KEY | D7: 원천 키 | E7: VARCHAR2(200) | F7: 필수 | G7: 원천 시스템의 PK · URL · Message-ID | H7: S01 중복 · 갱신 판정 | I7: hankyung:2026091500123
A8: 공통 | B8: 문서 | C8: DATA_SOURCE | D8: 사외/사내 | E8: VARCHAR2(16) | F8: 필수 | G8: 수집 경로 | H8: S10 필터 · S28 권한 | I8: EXTERNAL
A9: 공통 | B9: 문서 | C9: DOC_TYPE | D9: 문서 유형 | E9: VARCHAR2(32) | F9: 필수 | G9: 수집 경로 · 분류 | H9: S03 청킹 규칙 · S10 필터 | I9: NEWS
A10: 공통 | B10: 문서 | C10: TITLE | D10: 제목 | E10: VARCHAR2(1000 CHAR) | F10: 필수 | G10: 원문 | H10: S03 헤더 · S14 인용 | I10: 마이크론, 히로시마 HBM 라인 증설
A11: 공통 | B11: 문서 | C11: PUBLISHED_AT | D11: 작성 · 발행일시 | E11: DATE | F11: 필수 | G11: 원문 (없으면 NULL) | H11: S08 기간필터 · S12 최신성 · S19 센싱 | I11: 2026-09-15 08:12
A12: 공통 | B12: 문서 | C12: DATE_QUALITY | D12: 날짜 품질 | E12: VARCHAR2(10) | F12: 권장 | G12: EXACT / ESTIMATED / MISSING | H12: S08 필터 신뢰도 | I12: EXACT
A13: 공통 | B13: 문서 | C13: COLLECTED_AT | D13: 수집일시 | E13: DATE | F13: 필수 | G13: 수집 모듈 | H13: S01 운영 · 지연 점검 | I13: 2026-09-15 09:00
A14: 공통 | B14: 문서 | C14: ORG_NAME | D14: 기관 · 부서 | E14: VARCHAR2(200 CHAR) | F14: 필수 | G14: 언론사 · 증권사 · 기관 · 작성 부서 | H14: S03 헤더 · S14 인용 · 필터 | I14: 한국경제
A15: 공통 | B15: 문서 | C15: AUTHOR | D15: 작성자 | E15: VARCHAR2(200 CHAR) | F15: 권장 | G15: 기자 · 애널리스트 · 작성자 | H15: S14 인용 | I15: 김기술
A16: 공통 | B16: 문서 | C16: SRC_URL | D16: 원문 링크 · 경로 | E16: VARCHAR2(2000) | F16: 권장 | G16: URL 또는 파일 경로 | H16: UI 원문 이동 · 재파싱 | I16: https://…/2026/09/15/123
... A27: 공통 | B27: 청크 | C27: CHUNK_SEQ | D27: 순번 | E27: NUMBER(6) | F27: 필수 | G27: 분할 순서 | H27: 인접 확장 | I27: 1
A28: 공통 | B28: 청크 | C28: PARENT_ID | D28: 부모 청크 | E28: VARCHAR2(100) | F28: 선택 | G28: Parent-Child 구조 | H28: S03-4 · S13 확장
A29: 공통 | B29: 청크 | C29: CHUNK_KIND | D29: 청크 종류 | E29: VARCHAR2(10) | F29: 권장 | G29: TEXT / TABLE / SUMMARY | H29: S03 표 분리 · 수치 질문 | I29: TEXT
A30: 공통 | B30: 청크 | C30: SECTION_PATH | D30: 섹션 경로 | E30: VARCHAR2(1000 CHAR) | F30: 권장 | G30: 헤딩 · 안건 · 슬라이드 번호 | H30: S03 헤더 · 인용 | I30: 3. 공급 > 3.2 DRAM 증설
A31: 공통 | B31: 청크 | C31: HEADER_TEXT | D31: 문맥 헤더 | E31: VARCHAR2(1000 CHAR) | F31: 필수 | G31: [유형|날짜|기관|제목|섹션] 생성 | H31: S03-3 · S04 dense 입력 | I31: [뉴스 | 2026-09-15 | 한국경제 | 마이크론…]
A32: 공통 | B32: 청크 | C32: CHUNK_TEXT | D32: 청크 본문 | E32: CLOB | F32: 필수 | G32: 정제 후 분할 | H32: S04 임베딩 · S12 리랭크 | I32: 마이크론이 일본 히로시마 공장에…
A33: 공통 | B33: 청크 | C33: TOKEN_CNT | D33: 토큰 수 | E33: NUMBER(6) | F33: 권장 | G33: 임베딩 토크나이저 | H33: S04-1 잘림 점검 | I33: 412
A34: 공통 | B34: 청크 | C34: CHUNKER_VER | D34: 청커 버전 | E34: VARCHAR2(16) | F34: 권장 | G34: 분할 규칙 버전 | H34: 재청킹 비교 | I34: v2
A35: 소스별 | B35: 뉴스 | C35: publisher | D35: 언론사 | E35: VARCHAR2(100) | F35: 필수 | G35: 수집 메타 (= ORG_NAME) | H35: 필터 · 인용 | I35: 한국경제
A36: 소스별 | B36: 뉴스 | C36: reporter | D36: 기자 | E36: VARCHAR2(100) | F36: 권장 | G36: 기사 바이라인 | H36: 인용 | I36: 김기술
A37: 소스별 | B37: 뉴스 | C37: category | D37: 분야 | E37: VARCHAR2(50) | F37: 권장 | G37: 언론사 분류 | H37: 필터 · 센싱 축 매핑 | I37: IT/테크
A38: 소스별 | B38: 뉴스 | C38: cluster_id | D38: 사건 묶음 ID | E38: VARCHAR2(64) | F38: 권장 | G38: 근사 중복(MinHash) 묶음 대표 | H38: S01 재송고 · S18 센싱 | I38: EVT_20260915_HBM_MU
A39: 소스별 | B39: 뉴스 | C39: is_primary | D39: 대표 기사 | E39: CHAR(1) | F39: 권장 | G39: 묶음 중 가장 이른 기사 | H39: 중복 접기 | I39: Y
A40: 소스별 | B40: 뉴스 | C40: press_type | D40: 매체 유형 | E40: VARCHAR2(20) | F40: 선택 | G40: 종합지 · 산업지 · 통신사 | H40: 가중치 | I40: 종합지
... A95: 소스별 | B95: 임원 보고서 | C95: summary_slide | D95: 요약 슬라이드 번호 | E95: NUMBER(4) | F95: 권장 | G95: 파싱 | H95: 리랭크 가중 | I95: 2
A97: 정리하면서 놓치기 쉬운 것
A98: 필수(M) 판단 기준 | C98: 이 컬럼이 없으면 검색 · 권한 · 인용 중 하나가 깨지는 것만 M 으로 뒀습니다. 나머지는 R(권장) · O(선택)입니다.
A99: 공통 컬럼 우선 | C99: 필터 · 권한 · 정렬 · 인용에 쓰는 값은 META_EXTRA(JSON)가 아니라 공통 컬럼으로 올립니다. JSON 안의 값으로는 벡터 검색과 동시에 필터를 걸기 어렵습니다.
A100: 권한은 별도 테이블 | C100: 메일 수신자 · 결재선은 JSON 에 두면 권한 필터로 쓸 수 없습니다. RAG_DOC_ACL 행으로 풀어 넣고, Milvus 에는 acl 배열로 복제합니다.
A101: 날짜가 둘인 소스 | C101: 기관 보고서(발행일 vs 데이터 기준 시점), 지식문서(작성일 vs 최종 수정일)는 반드시 둘을 나눠 두고, 검색 기준으로 쓸 쪽을 PUBLISHED_AT 에 넣습니다.
A102: 사내 보유 여부 채우기 | C102: 오른쪽 두 칸(사내 보유 · 사내 컬럼명)을 채우면 그대로 매핑표가 됩니다. "파생 가능"은 다른 컬럼이나 본문에서 만들 수 있다는 뜻입니다.

Sheet 처리흐름_도식
A1: 소스별 처리 흐름 (청킹 전) — 셀 도식
A2: 색: 회색=입력 · 청록=핵심 처리 · 분홍=제거 · 흰색=일반 · 연두=청킹/메타 산출 · 세로로 여러 줄인 칸 = 분기
A4: 계열
A5: 웹 텍스트 | B5: 뉴스 · 지식문서 | D5: HTML 본문 추출 → 정규화
A6: PDF 문서 | B6: 증권사 · 기관 · 엔지니어 | D6: 레이아웃 파싱 → 표 분리
A7: 오피스 문서 | B7: 사내 보고서 · 임원 · 회의록 | D7: 형식 분기 → 슬라이드 · 헤딩
A8: 메일 | B8: 메일 (+ 첨부) | D8: 헤더 파싱 → 인용 · 서명 제거
A10: 1. 뉴스 | C10: 계열 · 웹 텍스트
A11: 원문 HTML · 텍스트 | B11: → | C11: 본문 추출 기사 본문만 | D11: → | E11: 노이즈 제거 광고 · 관련기사 | F11: → | G11: 재송고 판정 MinHash 대표 1건 | H11: → | I11: 청킹 기사 1건 = 1청크 | J11: → | K11: 메타 · 태그 언론사 · 회사 · 제품
A12: 청크 예시 | B12: [뉴스 | 2026-09-15 | 한국경제 | 마이크론, 일본 히로시마 HBM 라인 증설] 마이크론이 히로시마 공장에 HBM 전용 라인을 증설한다고 15일 밝혔다. 투자 규모는 …
A14: 2. 증권사 리포트 | C14: 계열 · PDF 문서
A15: 원문 PDF | B15: → | C15: 레이아웃 파싱 페이지 · 단 · 블록 | D15: → | E15: 제거 표지 · 면책 · 머리글 | F15: → | G15: ▸ 본문 · 섹션 단위 ▸ 표 · Markdown 표 ▸ 차트 · 캡션 · 제외 | H15: → | I15: 청킹 섹션 + 표 별도 | J15: → | K15: 메타 증권사 · 종목 · 의견
A16: 청크 예시 | B16: [증권사 | 2026-09-12 | ○○증권 | 메모리 3Q 프리뷰 | 표 2. 가격 전망] | 분기 | DRAM 계약가 QoQ | NAND 계약가 QoQ | | 3Q26 | +8% | +5% | | 4Q26 | +6% | +3% |
A18: 3. 기관 보고서 | C18: 계열 · PDF 문서
A19: 원문 긴 PDF | B19: → | C19: 목차 인식 장 · 절 경로 | D19: → | E19: 제거 표지 · 목차 · 부록 | F19: → | G19: 표 분리 표 제목 · 단위 | H19: → | I19: 기준 시점 데이터 시점 추출 | J19: → | K19: 청킹 헤딩 경로 단위
A20: 청크 예시 | B20: [기관 | 발행 2026-09-01 · 기준 2Q26 | ○○리서치 | 3. 공급 > 3.2 DRAM 증설] 2Q26 기준 DRAM 웨이퍼 생산능력은 전년 대비 …
A22: 4. 메일 | C22: 계열 · 메일
A23: 원문 EML · 본문 | B23: → | C23: 헤더 파싱 발신 · 수신 · 스레드 | D23: → | E23: 인용 제거 이전 메일 본문 | F23: → | G23: 서명 · 면책 제거 회사 서명 블록 | H23: → | I23: ▸ 본문 · 스레드 병합 ▸ 첨부 · 원 유형 파이프라인 | J23: → | K23: 청킹 · ACL 스레드 단위 · 수신자
A24: 청크 예시 | B24: [메일 | 2026-09-10 | 영업전략팀 | RE: 4Q 발주 조정 건 | 스레드 3통] (09-08 김OO) 고객사 A 4Q 발주 10% 하향 통보 … (09-10 이OO) 대응안 …
A26: 5. 회의록 | C26: 계열 · 오피스 문서
A27: 원문 문서 · 양식 | B27: → | C27: 양식 인식 일시 · 참석자 · 안건 | D27: → | E27: 필드 추출 결정 · 액션 아이템 | F27: → | G27: 안건 분할 안건별로 나눔 | H27: → | I27: 청킹 안건 = 1청크 | J27: → | K27: 메타 · ACL 참석자 · 주관 부서
A28: 청크 예시 | B28: [회의록 | 2026-09-17 | 시장분석팀 주간회의 | 안건 2. HBM 수요 점검] 결정: 4Q 전망 유지 / 액션: 고객별 발주 재확인 (박OO, 9/24)
A30: 6. 사내 보고서 | C30: 계열 · 오피스 문서
A31: 원문 PPT · Word · Excel | B31: → | C31: 버전 판정 최종본만 | D31: → | E31: ▸ PPT · 슬라이드 제목+본문 ▸ Word · 헤딩 구조 ▸ Excel · 시트 → 표 요약 | F31: → | G31: 정제 표지 · 목차 · 빈 슬라이드 | H31: → | I31: 청킹 슬라이드 · 헤딩 단위 | J31: → | K31: 메타 · ACL 부서 · 버전 · 등급
A32: 청크 예시 | B32: [사내보고서 | 2026-09-05 | 시장분석팀 | 3Q 메모리 수요 점검 v1.0 | 슬라이드 7] eSSD 수요 전망: 2026년 … EB (전년 대비 +…%)
A34: 7. 지식문서 | C34: 계열 · 웹 텍스트
A35: 원문 HTML · 위키 | B35: → | C35: 구조 보존 헤딩 · 목록 · 표 | D35: → | E35: 제거 메뉴 · 푸터 · 댓글 | F35: → | G35: 최신본 판정 최종 수정일 | H35: → | I35: 청킹 헤딩 단위 | J35: → | K35: 메타 소관 부서 · 수정일
A36: 청크 예시 | B36: [지식문서 | 수정 2026-08-30 | MIS | 용어 정의 > Sufficiency Ratio] 수급 충족률 = 공급 / 수요 …
A38: 8. 엔지니어 보고서 | C38: 계열 · PDF 문서
A39: 원문 PDF · 오피스 | B39: → | C39: 레이아웃 파싱 섹션 · 그림 · 표 | D39: → | E39: ▸ 본문 · 섹션 단위 ▸ 측정 표 · Markdown 표 ▸ 그래프 · 제목 · 축만 | F39: → | G39: 약어 풀이 공정 약어 사전 | H39: → | I39: 청킹 섹션 + 표 별도 | J39: → | K39: 메타 · ACL 공정 · 제품 · 과제
A40: 청크 예시 | B40: [엔지니어 | 2026-09-02 | ○○개발팀 | HBM4 12단 신뢰성 평가 | 표 3. 온도별 결과] | 조건 | 불량률 | …
A42: 9. 임원 보고서 | C42: 계열 · 오피스 문서
A43: 원문 PPT | B43: → | C43: 최종본 판정 보고 완료본 | D43: → | E43: 요약 우선 요약 · 결론 슬라이드 | F43: → | G43: 정제 표지 · 간지 | H43: → | I43: 청킹 슬라이드 단위 | J43: → | K43: ACL 등급 3 · 결재선
A44: 청크 예시 | B44: [임원보고 | 2026-09-11 | 전략기획 | 3Q 경영 현안 | 슬라이드 2. 요약] HBM 리스크: …

Sheet 처리흐름_판단기준
A1: 소스별 처리 흐름 — 단계별 처리 내용 · 판단 기준
A2: 맨 위 "선확인" 3행부터 · 연노랑 칸만 입력
A4: 소스 | B4: 단계 | C4: 처리 내용 | D4: 판단 기준 · 확인 방법 | E4: 현 수준 | F4: 상태 | G4: 메모
A5: ① 선확인 | B5: 원문 DB에 무엇이 저장돼 있나 | C5: ① 원본 파일(BLOB/경로) ② 추출 텍스트만 ③ HTML·구조 태그 포함 | D5: ② 텍스트만이면 표 · 헤딩 구조가 이미 사라졌을 수 있음 → PDF · 오피스 계열은 원본 재파싱이 필요한지 샘플로 판단 | F5: 미확인
A6: ① 선확인 | B6: 원본 파일에 다시 접근할 수 있나 | C6: 파일 서버 · 그룹웨어 · 메일 서버 경로가 doc id로 연결되는지 | D6: 접근 가능 → 계열별 파서로 재파싱 / 불가 → 텍스트 기반 정제만 (표 복원은 포기하고 표 청크 제외) | F6: 미확인
A7: ① 선확인 | B7: 기존 파서가 표 · 헤딩을 보존하나 | C7: 증권사 PDF 5건, 사내 PPT 5건을 원본과 나란히 비교 | D7: 보존 → 기존 파서 유지 + 정제만 추가 / 깨짐 → 해당 계열만 파서 교체 | F7: 미확인
A8: 뉴스 | B8: 본문 추출 | C8: 제목 · 본문 · 발행일시만 남김 | D8: 샘플 10건: 본문 앞뒤에 메뉴 · 기자 소개가 남는지 | F8: 미확인
A9: 뉴스 | B9: 노이즈 제거 | C9: 광고 문구, 관련기사 목록, 저작권 · 무단전재 문구, 기자 이메일 | D9: "무단 전재" "관련기사" 같은 패턴이 청크에 남는 비율 | F9: 미확인
A10: 뉴스 | B10: 재송고 판정 | C10: 본문 유사도 0.9 이상 묶기 → 가장 이른 기사 1건만 대표, 나머지는 링크로 | D10: 같은 사건 기사가 검색 상위를 채우는지 (센싱에서 특히 중요) | F10: 미확인
A11: 뉴스 | B11: 청킹 | C11: 기사 1건 = 1청크, 800토큰 넘으면 문단 경계로 2개 | D11: 청크 길이 분포, 기사 중간 잘림 | F11: 미확인
A12: 뉴스 | B12: 메타 · 태그 | C12: 언론사 · 발행일시 · URL + 사내 LLM으로 회사 · 제품 · 이벤트 태그 | D12: 태그 샘플 20건 정확도 | F12: 미확인
A13: 증권사 리포트 | B13: 레이아웃 파싱 | C13: 2단 편집 · 사이드바를 읽기 순서대로 | D13: 원본 PDF와 추출 텍스트 5건 비교: 좌우 단이 섞이는지 | F13: 미확인
A14: 증권사 리포트 | B14: 제거 | C14: 표지, Compliance Notice, 애널리스트 인증, 페이지마다 반복되는 머리글 · 바닥글 | D14: 면책 문구가 청크에 들어간 비율 (보통 가장 흔한 노이즈) | F14: 미확인
A15: 증권사 리포트 | B15: 분기 — 표 | C15: 표를 Markdown 표로, 표 제목 · 단위 · 기준 시점을 표 위에 붙임 | D15: 숫자가 행 · 열 위치를 잃지 않는지 (SM05 수치 질문으로 확인) | F15: 미확인
A16: 증권사 리포트 | B16: 분기 — 차트 | C16: 차트 제목 · 출처만 텍스트로, 수치는 사내 VLM 가능할 때만 | D16: 차트 수치를 묻는 질문 비중이 크면 VLM 검토 | F16: 미확인
... A48: 임원 보고서 | B48: ACL | C48: 보안등급 3 고정, ACL = 결재선 + 지정 그룹. 적재 직후 누출 테스트 | D48: 권한 없는 계정으로 SM04 · SM16 → "자료 없음" | F48: 미확인

Sheet P1_적재공통
A1: Phase 1 · 적재 공통 — 모든 소스에 해당 (소스별 차이는 소스별_상세)
A2: 연노랑 칸(현 수준 · 상태 · 메모)만 입력
A4: 단계 | B4: 단계명 | C4: No | D4: 체크 항목 | E4: 현 수준 | F4: 개선 방향 | G4: 우선 | H4: 상태 | I4: 메모
A5: S01 | B5: 수집 | C5: 01-1 | D5: 원천 키 유일 · 재수집 중복 체크 | E5: doc id 있음, 재수집 시 중복 체크 중 | F5: — | G5: P0 | H5: 완료
A6: S01 | B6: 수집 | C6: 01-2 | D6: 작성일 · 수집일 분리, 날짜 누락률 | E6: 분리 저장, 날짜 95% 보유 | F6: 누락 5%가 몰린 소스만 확인 | G6: P2 | H6: 완료
A7: S01 | B7: 수집 | C7: 01-3 | D7: 중복 수집 (뉴스 재송고 · 메일 인용) | F7: 해시 → 근사 중복(MinHash) | G7: P1 | H7: 미확인
A8: S02 | B8: 파싱 | C8: 02-1 | D8: 증권사 PDF 표 · 수치 보존 | F8: 표는 별도 청크, 파서 교체 검토 | G8: P1 | H8: 미확인
A9: S02 | B9: 파싱 | C9: 02-2 | D9: 메일 인용 · 서명 제거 | F9: 메일 정제 규칙 | G9: P1 | H9: 미확인
A10: S03 | B10: 청킹 | C10: 03-1 | D10: 분할 방식 · 크기 · 오버랩 | F10: 문서 유형별 규칙 (뉴스=기사, 리포트=섹션·표) | G10: P0 | H10: 미확인
A11: S03 | B11: 청킹 | C11: 03-2 | D11: 문장 잘림 · 표 깨짐 (샘플 20) | F11: 구조 기반 분할 | G11: P0 | H11: 미확인
A12: S03 | B12: 청킹 | C12: 03-3 | D12: 청크 헤더 [유형|날짜|기관|제목] | F12: HEADER_TEXT 별도 컬럼 | G12: P0 | H12: 미확인
A13: S04 | B13: 임베딩 | C13: 04-1 | D13: BGE-M3 max_length 잘림 여부 | F13: 잘림 0건 | G13: P0 | H13: 미확인
A14: S04 | B14: 임베딩 | C14: 04-2 | D14: dense만? sparse도? | F14: dense + sparse 동시 생성 | G14: P0 | H14: 미확인
A15: S04 | B15: 임베딩 | C15: 04-3 | D15: 입력 구성 | F15: dense=헤더+본문, sparse=본문만 | G15: P1 | H15: 미확인
A16: S05 | B16: 메타데이터 | C16: 05-1 | D16: 공통 컬럼 (유형 · 날짜 · 기관 · 보안등급) | F16: 필터에 쓰는 값은 공통 컬럼으로 | G16: P0 | H16: 미확인
A17: S05 | B17: 메타데이터 | C17: 05-2 | D17: 권한 원천 (메일 수신자 · 임원 결재선) | F17: ACL 테이블, 어려우면 보안등급만 1차 | G17: P0 | H17: 미확인
A18: S05 | B18: 메타데이터 | C18: 05-3 | D18: 회사 · 제품 · 주제 태그 | F18: 사내 LLM 추출 — Phase 2 기반 | G18: P1 | H18: 미확인
... A21: S06 | B21: 벡터 DB | C21: 06-3 | D21: Oracle 수정 · 삭제 반영 | F21: 증분 동기화 잡 | G21: P1 | H21: 미확인

Sheet P1_검색
A1: Phase 1 · 검색 — 질의가 흐르는 순서 (S07 → S15)
A2: 연노랑 칸(현 수준 · 상태 · 메모)만 입력
A4: 단계 | B4: 단계명 | C4: No | D4: 체크 항목 | E4: 현 수준 | F4: 개선 방향 | G4: 우선 | H4: 상태 | I4: 메모
A5: S07 | B5: 질의 입력 | C5: 07-1 | D5: 실제 질문 20개 스모크 테스트 | E5: 문항 작성 완료 (SM01~SM20) | F5: 실패 유형 5종 집계 → 우선순위 | G5: P0 | H5: 확인중
A6: S07 | B6: 질의 입력 | C6: 07-2 | D6: 질의 · 결과 · 답변 로그 | F6: Oracle 로그 테이블 3개 | G6: P0 | H6: 미확인
A7: S08 | B7: 질의 분석 · 분해 | C7: 08-1 | D7: 분해 시 고유명사 누락 | F7: 원 질의도 항상 함께 검색 | G7: P0 | H7: 미확인
A8: S08 | B8: 질의 분석 · 분해 | C8: 08-2 | D8: "최근 · 3분기" → 날짜 필터 | F8: 기간 추출 (규칙 우선) | G8: P0 | H8: 미확인
A9: S08 | B9: 질의 분석 · 분해 | C9: 08-3 | D9: 분해 적용 범위 | F9: 비교 · 종합형 질문에만 | G9: P1 | H9: 미확인
A10: S09 | B10: BM25 | C10: 09-1 | D10: 실행 위치 (파이썬 / Oracle Text / Milvus) | G10: P0 | H10: 미확인
A11: S09 | B11: BM25 | C11: 09-2 | D11: 토크나이저 — "하이닉스의 / 는" 동일 토큰? | F11: 형태소 분석 (Kiwi / Oracle Text) | G11: P0 | H11: 미확인
A12: S09 | B12: BM25 | C12: 09-3 | D12: BM25 vs BGE-M3 sparse | F12: 코드명 · 수치 질문으로 비교 후 택1 | G12: P1 | H12: 미확인
A13: S10 | B13: 시맨틱 검색 | C13: 10-1 | D13: 권한 · 기간 필터가 검색과 동시에 | F13: Milvus 사전 필터 (사후 필터 금지) | G13: P0 | H13: 미확인
A14: S10 | B14: 시맨틱 검색 | C14: 10-2 | D14: top-k | F14: 50 | G14: P1 | H14: 미확인
A15: S11 | B15: 결합 · 다양성 | C15: 11-1 | D15: 결합 방식 | E15: 계획만 있음 | F15: RRF k=60 | G15: P0 | H15: 미확인
A16: S11 | B16: 결합 · 다양성 | C16: 11-2 | D16: MMR 위치 · λ | E16: 계획만 있음 | F16: 리랭크 뒤, λ 0.5~0.7 | G16: P1 | H16: 미확인
A17: S11 | B17: 결합 · 다양성 | C17: 11-3 | D17: 문서당 청크 상한 | F17: 문서당 3개 | G17: P1 | H17: 미확인
A18: S12 | B18: 리랭크 | C18: 12-1 | D18: 모델 · 후보 수 → 최종 수 | F18: bge-reranker-v2-m3, 50 → 5~8 | G18: P0 | H18: 미확인
A19: S12 | B19: 리랭크 | C19: 12-2 | D19: 지연 | F19: p95 예산 안 | G19: P1 | H19: 미확인
A20: S13 | B20: 컨텍스트 | C20: 13-1 | D20: 청크 라벨 [번호|유형|기관|날짜] | F20: 라벨 필수 | G20: P0 | H20: 미확인
A21: S13 | B21: 컨텍스트 | C21: 13-2 | D21: 넘기는 청크 수 | F21: 토큰 예산 기준 | G21: P1 | H21: 미확인
A22: S14 | B22: LLM 답변 | C22: 14-1 | D22: 출처 번호 인용 | F22: 문장별 인용 강제 | G22: P0 | H22: 미확인
A23: S14 | B23: LLM 답변 | C23: 14-2 | D23: 근거 없을 때 | F23: "확인된 자료 없음" 응답 | G23: P0 | H23: 미확인
A24: S14 | B24: LLM 답변 | C24: 14-3 | D24: 자료 간 시점 · 수치 충돌 | F24: 둘 다 날짜와 함께 제시 | G24: P1 | H24: 미확인
A25: S15 | B25: 평가 | C25: 15-1 | D25: 골든셋 | F25: 문서 ID + 정답 문장 (청크 ID 금지) | G25: P0 | H25: 미확인
A26: S15 | B26: 평가 | C26: 15-2 | D26: 검색 지표 · 단계별 비교 | F26: Recall@k · MRR, BM25/Dense/Hybrid/+Rerank | G26: P0 | H26: 미확인
A27: S15 | B27: 평가 | C27: 15-3 | D27: 답변 채점 | F27: 사내 LLM + 20문항 사람 교차 | G27: P1 | H27: 미확인

Sheet P2_센싱
A1: Phase 2 · 마켓 센싱 (S16 → S21)
A2: 연노랑 칸(현 수준 · 상태 · 메모)만 입력
A4: 단계 | B4: 단계명 | C4: No | D4: 체크 항목 | E4: 현 수준 | F4: 개선 방향 | G4: 우선 | H4: 상태 | I4: 메모
A5: S16 | B5: 센싱 축 | C5: 16-1 | D5: 축 확정 | E5: 6축 전부 사용 (수요 · 공급 · 가격 · 기술 · 정책 · 고객) | F5: — | G5: P0 | H5: 완료
A6: S16 | B6: 센싱 축 | C6: 16-2 | D6: 축당 하위 신호 3~5 + "이상" 정의 | F6: 축별 담당자와 한 문장씩 | G6: P0 | H6: 미확인
A7: S17 | B7: 상시 질의 | C7: 17-1 | D7: 신호당 질의 2~4개 (한 · 영) | F7: 사내 LLM 초안 + 검수 | G7: P0 | H7: 미확인
A8: S17 | B8: 상시 질의 | C8: 17-2 | D8: 기간 창 · 태그 필터 템플릿 | F8: 이번 주 vs 지난 4주 | G8: P0 | H8: 미확인
A9: S18 | B9: 검색 · 수집 | C9: 18-1 | D9: 하이브리드 재사용 + 기간 창 | F9: Phase 1 S10 그대로 | G9: P0 | H9: 미확인
A10: S18 | B10: 검색 · 수집 | C10: 18-2 | D10: 재송고 뉴스 접기 | F10: MinHash + MMR → 사건 단위 | G10: P0 | H10: 미확인
A11: S19 | B11: 변화 감지 | C11: 19-1 | D11: 언급량 급증 | F11: 지난 4주 평균 대비 z-score | G11: P0 | H11: 미확인
A12: S19 | B12: 변화 감지 | C12: 19-2 | D12: 새 엔티티 · 방향 변화 | F12: 백테스트에서 이득 있으면 추가 | G12: P1 | H12: 미확인
A13: S19 | B13: 변화 감지 | C13: 19-3 | D13: 축 점수 집계 → 정렬 | E13: 신호 뚜렷한 축을 위로 (요구사항) | F13: 하위 신호 점수 → 축 점수(최대값) | G13: P0 | H13: 미확인
A14: S20 | B14: 요약 · 알림 | C14: 20-1 | D14: 축 점수순 리포트 + 근거 인용 | F14: 주간 리포트 + 임계 초과 즉시 | G14: P0 | H14: 미확인
A15: S20 | B15: 요약 · 알림 | C15: 20-2 | D15: 담당자 유효 / 무효 표시 | F15: 임계 조정 근거 | G15: P1 | H15: 미확인
A16: S21 | B16: 백테스트 | C16: 21-1 | D16: 과거 실제 사건 10건 | F16: 감산 · 가격 급등 · 규제 | G16: P0 | H16: 미확인
A17: S21 | B17: 백테스트 | C17: 21-2 | D17: 회수율 · 오탐 | F17: 임계 · 질의 조정 | G17: P0 | H17: 미확인

Sheet P3_정형연계
A1: Phase 3 · 정형 데이터 연계 — 사내 DB · SQL × 비정형 (S22 → S29)
A2: 연노랑 칸(현 수준 · 상태 · 메모)만 입력
A4: 단계 | B4: 단계명 | C4: No | D4: 체크 항목 | E4: 현 수준 | F4: 개선 방향 | G4: 우선 | H4: 상태 | I4: 메모
A5: S22 | B5: 정형 자산 카탈로그 | C5: 22-1 | D5: 대상 테이블 · 뷰 목록 — 소유 부서 · 갱신 주기 · 행 수 · 보존 기간 | F5: 연계 1차 대상 5~10개로 한정 (판매 · 수급 · 가격 · 재고 · 생산) | G5: P0 | H5: 미확인
A6: S22 | B6: 정형 자산 카탈로그 | C6: 22-2 | D6: 지표 정의서 — 업무 용어 → 컬럼 · 집계식 · 단위 · 기간 | F6: "수급 충족률", "계약가", "출하량"을 SQL 식으로 1:1 정의. 이게 없으면 Text-to-SQL은 시작 불가 | G6: P0 | H6: 미확인
A7: S22 | B7: 정형 자산 카탈로그 | C7: 22-3 | D7: 코드값 사전 — 제품 · 고객 · 지역 코드 ↔ 이름 · 약어 · 별칭 | F7: 질문의 "HBM3E 12단"을 PRODUCT_CODE 목록으로 바꾸는 표 | G7: P0 | H7: 미확인
A8: S22 | B8: 정형 자산 카탈로그 | C8: 22-4 | D8: 컬럼 설명 · 샘플값 · NULL 비율 | F8: LLM 프롬프트에 넣을 스키마 설명의 재료 | G8: P1 | H8: 미확인
A9: S23 | B9: 시맨틱 뷰 · 허용목록 | C9: 23-1 | D9: LLM이 조회할 분석 전용 뷰 (표준 컬럼명 · 단위 · 기간) | F9: 원본 테이블 직접 조회 금지. 조인 · 단위 환산은 뷰 안에서 끝냄 | G9: P0 | H9: 미확인
A10: S23 | B10: 시맨틱 뷰 · 허용목록 | C10: 23-2 | D10: allow-list — 조회 허용 테이블 · 컬럼 목록 | F10: 목록 밖은 생성 SQL 단계에서 차단 | G10: P0 | H10: 미확인
A11: S23 | B11: 시맨틱 뷰 · 허용목록 | C11: 23-3 | D11: 동의어 · 별칭 매핑 (질문 표현 → 코드 · 컬럼) | F11: S27 사내 용어 사전과 같은 사전 공유 | G11: P1 | H11: 미확인
A12: S23 | B12: 시맨틱 뷰 · 허용목록 | C12: 23-4 | D12: 기간 표현 표준 (분기 · 회계연도 · 주차) | F12: "3분기"가 회계 기준인지 달력 기준인지 고정 | G12: P1 | H12: 미확인
A13: S24 | B13: 질의 라우팅 | C13: 24-1 | D13: 질문 분류 기준 — 정형 / 비정형 / 혼합 / 불가 | F13: 수치 · 집계 · 추이 · 비교 → 정형, 경위 · 이유 · 동향 → 비정형 | G13: P0 | H13: 미확인
A14: S24 | B14: 질의 라우팅 | C14: 24-2 | D14: 분류기 구현 (규칙 우선 + 사내 LLM 보조) | F14: 엔티티가 코드 사전에 있으면 정형 가중 | G14: P0 | H14: 미확인
A15: S24 | B15: 질의 라우팅 | C15: 24-3 | D15: 혼합 질문 분해 — 수치부 / 설명부 | F15: "왜 올랐나" = SQL(추이) + RAG(이유) | G15: P1 | H15: 미확인
A16: S24 | B16: 질의 라우팅 | C16: 24-4 | D16: 불가 질문 처리 (데이터 없음 · 권한 없음) | F16: 되묻기 또는 "확인 불가" 응답 | G16: P1 | H16: 미확인
... A37: S29 | B37: 평가 · 운영 | C37: 29-4 | D37: 스키마 변경 감지 → 카탈로그 갱신 | F37: 컬럼 변경 시 프롬프트 · allow-list 자동 갱신 | G37: P1 | H37: 미확인

Sheet 정형연계_패턴
A1: 정형 × 비정형 결합 패턴 (Phase 3)
A2: 질문 유형별로 A~D 중 하나를 쓴다 · 색: 회색=입력 · 청록=핵심 · 분홍=거절 · 연두=산출
A4: 라우팅
A5: 질문 사용자 입력 | B5: → | C5: 질의 분석 기간 · 엔티티 추출 | D5: → | E5: 라우팅 4갈래 분류 | F5: → | G5: ▸ 정형 · SQL ▸ 비정형 · RAG ▸ 혼합 · SQL + RAG ▸ 불가 · 되묻기
A7: 패턴 A · 수치 + 설명 (혼합 질문의 기본형) | D7: "3분기 eSSD 출하량과 그렇게 본 이유는?" — 숫자는 DB, 맥락은 문서에서 가져와 한 답변으로
A8: 혼합 질문 수치부 + 설명부 | B8: → | C8: ▸ SQL 경로 · 뷰 조회 → 표 ▸ RAG 경로 · 하이브리드 검색 | D8: → | E8: 컨텍스트 합치기 표 + 청크 + 출처 라벨 | F8: → | G8: LLM 답변 수치 출처 + 문서 인용
A9: 출력 예시 | B9: [DB | V_SALES_MONTHLY | 제품=eSSD, 기간=3Q26 | SUM(출하량) | 2026-09-20 10:12] | 월 | 출하량(EB) | | 7월 | 9.8 | | 8월 | 10.4 | [문서 3 | 사내보고서 | 2026-09-05 | 3Q 수요 점검] AI 서버 스토리지 확대가 주 요인 …
A11: 패턴 B · 문서 → DB 검증 | D11: 문서에 적힌 수치가 맞는지 DB로 확인한다. 보고서 인용 오류 · 구버전 자료를 걸러낸다
A12: 질문 문서 기반 | B12: → | C12: RAG 검색 근거 문서 | D12: → | E12: 수치 · 엔티티 추출 LLM | F12: → | G12: SQL 검증 조회 같은 조건으로 | H12: → | I12: 일치 여부 표시 일치 / 차이 / 미확인
A13: 출력 예시 | B13: 문서(2026-09-05): eSSD 수요 120EB DB(V_DEMAND, 조회 2026-09-20): 118.6EB → 차이 1.4EB (문서가 예측치, DB는 실적 반영)
A15: 패턴 C · SQL → 요약 + 근거 | D15: "왜 올랐나" — 추이는 DB에서 뽑고, 변화 시점의 근거 문서를 검색해 설명을 붙인다
A16: 수치 질문 추이 · 변화 | B16: → | C16: SQL 기간별 집계 | D16: → | E16: 변화 구간 탐지 급증 · 급감 시점 | F16: → | G16: 그 기간 문서 검색 RAG + 기간 필터 | H16: → | I16: 요약 수치 + 원인 후보
A17: 출력 예시 | B17: [DB] 8월 계약가 +8% (전월 대비) [근거] 증권사 리포트 2026-08-12: 서버 수요 견조 … / 뉴스 2026-08-09: 경쟁사 감산 발표
A19: 패턴 D · 센싱 연계 (Phase 2와 결합) | D19: 외부 신호(뉴스)와 내부 지표(DB)를 같은 축에서 비교한다. 외부만 움직이는지, 내부 실적도 따라오는지 구분
A20: 센싱 축 · 신호 S16 정의 | B20: → | C20: ▸ 외부 · 뉴스 언급량 · 논조 ▸ 내부 · DB 지표 추이 | D20: → | E20: 교차 비교 동행 · 선행 · 괴리 | F20: → | G20: 알림 · 리포트 축 점수 + 근거
A21: 출력 예시 | B21: 가격 축: 외부 언급량 ×2.8 (이번 주) / 내부 계약가 +1.2% (같은 주) → 외부 선행, 내부 반영 지연 관찰
A23: 기존 단계와의 연결
A24: 기존 단계 (Phase 1 · 2) | C24: Phase 3에서 | E24: 무엇이 달라지나
A25: S08 질의 분석 · 분해 | C25: S24 라우팅으로 확장 | E25: 기간 · 엔티티 추출 결과를 라우팅 판단과 SQL WHERE 절에 함께 사용
A26: S13 컨텍스트 구성 | C26: S26 결합 | E26: 청크만이 아니라 표(Markdown)와 쿼리 출처 라벨도 컨텍스트에 포함
A27: S14 LLM 답변 | C27: S27 정합성 | E27: 문장별 인용 규칙에 "수치는 DB 출처 표기"를 추가
A28: S15 평가 | C28: S29 평가 | E28: 골든셋에 정형 · 혼합 문항 추가, 지표에 실행결과 정확도 추가
A29: S05 메타 · 권한 | C29: S28 권한 | E29: 비정형 ACL과 정형 행 · 열 권한을 같은 사용자 그룹 체계로
A30: S19 변화 감지 (Phase 2) | C30: 패턴 D | E30: 외부 신호와 내부 지표를 같은 축에서 교차 비교

Sheet 스모크20
A1: 스모크 테스트 20문항 — 사내에서 돌리고 결과만 입력
A2: 질문 원문 · 기대 근거는 smoke_test_20_rev1.html · 실패 유형 ①검색 누락 ②엉뚱한 청크 ③파싱 깨짐 ④답변 환각 ⑤권한 노출
A4: No | B4: 유형 | C4: 질문 (요약) | D4: 검색 판정 | E4: 답변 판정 | F4: 실패 유형 | G4: 메모
A5: SM01 | B5: 사실 | C5: 마이크론 HBM 생산 확대 계획
A6: SM02 | B6: 사실 | C6: Sufficiency Ratio 정의
A7: SM03 | B7: 사실 | C7: 최근 주간회의 액션 아이템
A8: SM04 | B8: 사실 | C8: 임원 보고 HBM 리스크 (권한)
A9: SM05 | B9: 수치 | C9: 2H26 DRAM 계약가 분기별
A10: SM06 | B10: 수치 | C10: 2026 HBM 시장 규모 · 성장률
A11: SM07 | B11: 수치 | C11: 당사 eSSD 수요 (EB)
A12: SM08 | B12: 수치 | C12: 엔비디아 최근 DC 매출
A13: SM09 | B13: 기간 | C13: 최근 2주 CXMT 뉴스
A14: SM10 | B14: 기간 | C14: 3Q NAND 전망 상향 증권사
A15: SM11 | B15: 기간 | C15: 이번 달 고객 발주 조정 메일 (권한)
A16: SM12 | B16: 종합 | C16: 하이퍼스케일러 CapEx 사외 vs 사내
... A24: SM20 | B24: 답없음 | C24: TSMC DRAM 출하량 (전제 오류)
